export class AppError extends Error {
  public statusCode: number;
  public status: string;
  public isOperational: boolean;

  constructor(message: string, statusCode: number) {
    super(message);
    this.statusCode = statusCode;
    this.status = `${statusCode}`.startsWith('4') ? 'fail' : 'error';
    this.isOperational = true;

    Error.captureStackTrace(this, this.constructor);
  }
}

export class ValidationError extends AppError {
  constructor(message: string) {
    super(message, 400);
  }
}

export class AuthenticationError extends AppError {
  constructor(message: string = 'Not authenticated') {
    super(message, 401);
  }
}

export class AuthorizationError extends AppError {
  constructor(message: string = 'Not authorized') {
    super(message, 403);
  }
}

export class NotFoundError extends AppError {
  constructor(message: string = 'Resource not found') {
    super(message, 404);
  }
}

export class ConflictError extends AppError {
  constructor(message: string = 'Resource already exists') {
    super(message, 409);
  }
}

export const catchAsync = (fn: Function) => {
  return (req: any, res: any, next: any) => {
    fn(req, res, next).catch(next);
  };
};
